âœ… Auditlog registered for all security-sensitive models
Traceback (most recent call last):
  File "/Users/saidamenmambayao/Library/Mobile Documents/com~apple~CloudDocs/BTA/OOBC/obcms/src/manage.py", line 22, in <module>
    main()
  File "/Users/saidamenmambayao/Library/Mobile Documents/com~apple~CloudDocs/BTA/OOBC/obcms/src/manage.py", line 18, in main
    execute_from_command_line(sys.argv)
  File "/Users/saidamenmambayao/Library/Mobile Documents/com~apple~CloudDocs/BTA/OOBC/obcms/venv/lib/python3.12/site-packages/django/core/management/__init__.py", line 442, in execute_from_command_line
    utility.execute()
  File "/Users/saidamenmambayao/Library/Mobile Documents/com~apple~CloudDocs/BTA/OOBC/obcms/venv/lib/python3.12/site-packages/django/core/management/__init__.py", line 436, in execute
    self.fetch_command(subcommand).run_from_argv(self.argv)
  File "/Users/saidamenmambayao/Library/Mobile Documents/com~apple~CloudDocs/BTA/OOBC/obcms/venv/lib/python3.12/site-packages/django/core/management/base.py", line 416, in run_from_argv
    self.execute(*args, **cmd_options)
  File "/Users/saidamenmambayao/Library/Mobile Documents/com~apple~CloudDocs/BTA/OOBC/obcms/venv/lib/python3.12/site-packages/django/core/management/base.py", line 457, in execute
    self.check(**check_kwargs)
  File "/Users/saidamenmambayao/Library/Mobile Documents/com~apple~CloudDocs/BTA/OOBC/obcms/venv/lib/python3.12/site-packages/django/core/management/base.py", line 492, in check
    all_issues = checks.run_checks(
                 ^^^^^^^^^^^^^^^^^^
  File "/Users/saidamenmambayao/Library/Mobile Documents/com~apple~CloudDocs/BTA/OOBC/obcms/venv/lib/python3.12/site-packages/django/core/checks/registry.py", line 89, in run_checks
    new_errors = check(app_configs=app_configs, databases=databases)
                 ^^^^^^^^^^^^^^^^^^^^^^^^^^^^^^^^^^^^^^^^^^^^^^^^^^^
  File "/Users/saidamenmambayao/Library/Mobile Documents/com~apple~CloudDocs/BTA/OOBC/obcms/venv/lib/python3.12/site-packages/django/core/checks/urls.py", line 136, in check_custom_error_handlers
    handler = resolver.resolve_error_handler(status_code)
              ^^^^^^^^^^^^^^^^^^^^^^^^^^^^^^^^^^^^^^^^^^^
  File "/Users/saidamenmambayao/Library/Mobile Documents/com~apple~CloudDocs/BTA/OOBC/obcms/venv/lib/python3.12/site-packages/django/urls/resolvers.py", line 732, in resolve_error_handler
    callback = getattr(self.urlconf_module, "handler%s" % view_type, None)
                       ^^^^^^^^^^^^^^^^^^^
  File "/Users/saidamenmambayao/Library/Mobile Documents/com~apple~CloudDocs/BTA/OOBC/obcms/venv/lib/python3.12/site-packages/django/utils/functional.py", line 47, in __get__
    res = instance.__dict__[self.name] = self.func(instance)
                                         ^^^^^^^^^^^^^^^^^^^
  File "/Users/saidamenmambayao/Library/Mobile Documents/com~apple~CloudDocs/BTA/OOBC/obcms/venv/lib/python3.12/site-packages/django/urls/resolvers.py", line 711, in urlconf_module
    return import_module(self.urlconf_name)
           ^^^^^^^^^^^^^^^^^^^^^^^^^^^^^^^^
  File "/opt/homebrew/Cellar/python@3.12/3.12.11/Frameworks/Python.framework/Versions/3.12/lib/python3.12/importlib/__init__.py", line 90, in import_module
    return _bootstrap._gcd_import(name[level:], package, level)
           ^^^^^^^^^^^^^^^^^^^^^^^^^^^^^^^^^^^^^^^^^^^^^^^^^^^^
  File "<frozen importlib._bootstrap>", line 1387, in _gcd_import
  File "<frozen importlib._bootstrap>", line 1360, in _find_and_load
  File "<frozen importlib._bootstrap>", line 1331, in _find_and_load_unlocked
  File "<frozen importlib._bootstrap>", line 935, in _load_unlocked
  File "<frozen importlib._bootstrap_external>", line 999, in exec_module
  File "<frozen importlib._bootstrap>", line 488, in _call_with_frames_removed
  File "/Users/saidamenmambayao/Library/Mobile Documents/com~apple~CloudDocs/BTA/OOBC/obcms/src/obc_management/urls.py", line 32, in <module>
    from common.views.health import health_check, readiness_check
  File "/Users/saidamenmambayao/Library/Mobile Documents/com~apple~CloudDocs/BTA/OOBC/obcms/src/common/views/__init__.py", line 3, in <module>
    from .auth import (
  File "/Users/saidamenmambayao/Library/Mobile Documents/com~apple~CloudDocs/BTA/OOBC/obcms/src/common/views/auth.py", line 10, in <module>
    from ..forms import CustomLoginForm, UserRegistrationForm
  File "/Users/saidamenmambayao/Library/Mobile Documents/com~apple~CloudDocs/BTA/OOBC/obcms/src/common/forms/__init__.py", line 20, in <module>
    from .staff import (
  File "/Users/saidamenmambayao/Library/Mobile Documents/com~apple~CloudDocs/BTA/OOBC/obcms/src/common/forms/staff.py", line 492, in <module>
    class StaffTaskForm(forms.ModelForm):
  File "/Users/saidamenmambayao/Library/Mobile Documents/com~apple~CloudDocs/BTA/OOBC/obcms/venv/lib/python3.12/site-packages/django/forms/models.py", line 312, in __new__
    fields = fields_for_model(
             ^^^^^^^^^^^^^^^^^
  File "/Users/saidamenmambayao/Library/Mobile Documents/com~apple~CloudDocs/BTA/OOBC/obcms/venv/lib/python3.12/site-packages/django/forms/models.py", line 237, in fields_for_model
    formfield = f.formfield(**kwargs)
                ^^^^^^^^^^^^^^^^^^^^^
  File "/Users/saidamenmambayao/Library/Mobile Documents/com~apple~CloudDocs/BTA/OOBC/obcms/venv/lib/python3.12/site-packages/django/db/models/fields/related.py", line 2044, in formfield
    "queryset": self.remote_field.model._default_manager.using(using),
                ^^^^^^^^^^^^^^^^^^^^^^^^^^^^^^^^^^^^^^^^
AttributeError: 'str' object has no attribute '_default_manager'
