INFO Loading faiss.
INFO Successfully loaded faiss.
âœ… Auditlog registered for all security-sensitive models
Traceback (most recent call last):
  File "/Users/saidamenmambayao/Library/Mobile Documents/com~apple~CloudDocs/BTA/OOBC/obcms/src/manage.py", line 22, in <module>
    main()
  File "/Users/saidamenmambayao/Library/Mobile Documents/com~apple~CloudDocs/BTA/OOBC/obcms/src/manage.py", line 18, in main
    execute_from_command_line(sys.argv)
  File "/Users/saidamenmambayao/Library/Mobile Documents/com~apple~CloudDocs/BTA/OOBC/obcms/venv/lib/python3.12/site-packages/django/core/management/__init__.py", line 442, in execute_from_command_line
    utility.execute()
  File "/Users/saidamenmambayao/Library/Mobile Documents/com~apple~CloudDocs/BTA/OOBC/obcms/venv/lib/python3.12/site-packages/django/core/management/__init__.py", line 436, in execute
    self.fetch_command(subcommand).run_from_argv(self.argv)
  File "/Users/saidamenmambayao/Library/Mobile Documents/com~apple~CloudDocs/BTA/OOBC/obcms/venv/lib/python3.12/site-packages/django/core/management/commands/test.py", line 24, in run_from_argv
    super().run_from_argv(argv)
  File "/Users/saidamenmambayao/Library/Mobile Documents/com~apple~CloudDocs/BTA/OOBC/obcms/venv/lib/python3.12/site-packages/django/core/management/base.py", line 416, in run_from_argv
    self.execute(*args, **cmd_options)
  File "/Users/saidamenmambayao/Library/Mobile Documents/com~apple~CloudDocs/BTA/OOBC/obcms/venv/lib/python3.12/site-packages/django/core/management/base.py", line 460, in execute
    output = self.handle(*args, **options)
             ^^^^^^^^^^^^^^^^^^^^^^^^^^^^^
  File "/Users/saidamenmambayao/Library/Mobile Documents/com~apple~CloudDocs/BTA/OOBC/obcms/venv/lib/python3.12/site-packages/django/core/management/commands/test.py", line 63, in handle
    failures = test_runner.run_tests(test_labels)
               ^^^^^^^^^^^^^^^^^^^^^^^^^^^^^^^^^^
  File "/Users/saidamenmambayao/Library/Mobile Documents/com~apple~CloudDocs/BTA/OOBC/obcms/venv/lib/python3.12/site-packages/django/test/runner.py", line 1085, in run_tests
    suite = self.build_suite(test_labels)
            ^^^^^^^^^^^^^^^^^^^^^^^^^^^^^
  File "/Users/saidamenmambayao/Library/Mobile Documents/com~apple~CloudDocs/BTA/OOBC/obcms/venv/lib/python3.12/site-packages/django/test/runner.py", line 940, in build_suite
    tests = self.load_tests_for_label(label, discover_kwargs)
            ^^^^^^^^^^^^^^^^^^^^^^^^^^^^^^^^^^^^^^^^^^^^^^^^^
  File "/Users/saidamenmambayao/Library/Mobile Documents/com~apple~CloudDocs/BTA/OOBC/obcms/venv/lib/python3.12/site-packages/django/test/runner.py", line 921, in load_tests_for_label
    tests = self.test_loader.discover(start_dir=label, **kwargs)
            ^^^^^^^^^^^^^^^^^^^^^^^^^^^^^^^^^^^^^^^^^^^^^^^^^^^^
  File "/opt/homebrew/Cellar/python@3.12/3.12.11/Frameworks/Python.framework/Versions/3.12/lib/python3.12/unittest/loader.py", line 310, in discover
    tests = list(self._find_tests(start_dir, pattern))
            ^^^^^^^^^^^^^^^^^^^^^^^^^^^^^^^^^^^^^^^^^^
  File "/opt/homebrew/Cellar/python@3.12/3.12.11/Frameworks/Python.framework/Versions/3.12/lib/python3.12/unittest/loader.py", line 374, in _find_tests
    yield from self._find_tests(full_path, pattern)
  File "/opt/homebrew/Cellar/python@3.12/3.12.11/Frameworks/Python.framework/Versions/3.12/lib/python3.12/unittest/loader.py", line 366, in _find_tests
    tests, should_recurse = self._find_test_path(full_path, pattern)
                            ^^^^^^^^^^^^^^^^^^^^^^^^^^^^^^^^^^^^^^^^
  File "/opt/homebrew/Cellar/python@3.12/3.12.11/Frameworks/Python.framework/Versions/3.12/lib/python3.12/unittest/loader.py", line 418, in _find_test_path
    raise ImportError(
ImportError: 'tests' module incorrectly imported from '/Users/saidamenmambayao/Library/Mobile Documents/com~apple~CloudDocs/BTA/OOBC/obcms/src/budget_preparation/tests'. Expected '/Users/saidamenmambayao/Library/Mobile Documents/com~apple~CloudDocs/BTA/OOBC/obcms/src/budget_preparation'. Is this module globally installed?
